<mujoco model="end_effector">
  <compiler angle="radian" meshdir="assets" autolimits="true"/>

  <option timestep="0.0005"/>

  <worldbody>
    <light name="top" pos="0 0 2" mode="trackcom"/>
    <body name="base_link">
      <!-- TODO:  check friction coefficients. -->
      <geom type="sphere" size="0.0195" mass="0.057" priority="1" condim="3" friction="0.6 .01 .003"/>
      <!-- TODO:  change range limits to better suit task. -->
        <joint name="end_effector_x" type="slide" range="0.15 0.75" axis="1 0 0" limited="true"/>
          <joint name="end_effector_y" type="slide" range="-0.6 0.6" axis="0 1 0" limited="true"/>
            <joint name="end_effector_z" type="slide" range="-0.03 0.3" axis="0 0 1" limited="true"/>
            <site name="eeff" pos="0 0 0.0" group="3"/>
    </body>
  </worldbody>

  <actuator>
    <general site="eeff" refsite="world" gaintype="fixed" forcerange="-10 10" ctrlrange="-1 1" forcelimited="true" ctrllimited="true" gainprm="10" gear="1 0 0 0 0 0"/>
    <general site="eeff" refsite="world" gaintype="fixed" forcerange="-10 10" ctrlrange="-1 1" forcelimited="true" ctrllimited="true" gainprm="10" gear="0 1 0 0 0 0"/>
    <general site="eeff" refsite="world" gaintype="fixed" forcerange="-10 10" ctrlrange="-1 1" forcelimited="true" ctrllimited="true" gainprm="10" gear="0 0 1 0 0 0"/>
  </actuator>
</mujoco>
